Workbook
Name Level1: [1]Data_1!$E$23:$E$25
Name Level1: [2]Data_1!$E$23:$E$25
Name Logic: [1]Data_1!$J$23:$K$25
Name Logic: [2]Data_1!$J$23:$K$25
Name VP1_: [1]Data_1!$N$61:$N$64
Name VP1_N: [1]Data_1!$N$23:$N$47
Name VP2_: [1]Data_1!$P$61:$P$65
Name VP2_N: [1]Data_1!$P$23:$P$51
Name VP3_: [1]Data_1!$R$61:$R$67
Name VP3_N: [1]Data_1!$R$23:$R$55

Sheet Bar Graph back up
A1: Plan No. | B1: Team Action Plan | C1: Progress | D1: Max
A2: 1 | B2: =#REF! -> #REF! | C2: =#REF! -> #REF! | D2: 1
A3: 2 | B3: =#REF! -> #REF! | C3: =#REF! -> #REF! | D3: 1
A4: 3 | B4: =#REF! -> #REF! | C4: =#REF! -> #REF! | D4: 1
A5: 4 | B5: =#REF! -> #REF! | C5: =#REF! -> #REF! | D5: 1
A6: 5 | B6: =#REF! -> #REF! | C6: =#REF! -> #REF! | D6: 1
A7: Plan No. | B7: Team Action Plan | C7: Progress | D7: Max
A8: 6 | B8: =#REF! -> #REF! | C8: =#REF! -> #REF! | D8: 1
A9: 7 | B9: =#REF! -> #REF! | C9: =#REF! -> #REF! | D9: 1
A10: 8 | B10: =#REF! -> #REF! | C10: =#REF! -> #REF! | D10: 1
A11: 9 | B11: =#REF! -> #REF! | C11: =#REF! -> #REF! | D11: 1
A12: 10 | B12: =#REF! -> #REF! | C12: =#REF! -> #REF! | D12: 1
A13: Plan No. | B13: Team Action Plan | C13: Progress | D13: Max
A14: 11 | B14: =#REF! -> #REF! | C14: =#REF! -> #REF! | D14: 1
A15: 12 | B15: =#REF! -> #REF! | C15: =#REF! -> #REF! | D15: 1
A16: 13 | B16: =#REF! -> #REF! | C16: =#REF! -> #REF! | D16: 1
A17: 14 | B17: =#REF! -> #REF! | C17: =#REF! -> #REF! | D17: 1
A18: 15 | B18: =#REF! -> #REF! | C18: =#REF! -> #REF! | D18: 1

Sheet ประมาณการคะแนน หัวข้อ RM&IC
A1: ประมาณการคะแนน Enabler : Risk Management & Internal Control
A2: No. | B2: Enabler | C2: หัวข้อ | D2: ประเด็นย่อย | E2: ร้อยละ | F2: ประมาณจากคะแนนที่นำส่งข้อมูลในระบบ สคร.ปี 66 | G2: 2567 (ประมาณการจาก OFI รอบที่ 1 | H2: คะแนน สคร. ปี 66* (คะแนนรายหัวข้อย่อย เป็นการประมาณการ) | I2: 2563 | J2: 2564 | K2: 2565 | L2: 2566 | M2: คะแนน สคร. ปี 2567 | N2: คะแนน สคร. ปี 2568 | O2: 2569 | P2: 2570
A3: 3 | B3: RM&IC | C3: 1. ธรรมาภิบาลและวัฒนธรรมองค์กร (น้ำหนักร้อยละ 15) | D3: 1.1 บทบาทคณะกรรมการในการกำกับติดตามการบริหารความเสี่ยงและการพัฒนาระบบการควบคุมภายใน | E3: 4 | F3: 1.5 | G3: 3 | H3: 3.35 | I3: 3.35 | J3: 3.35 | K3: 3.35 | L3: 3.35 | M3: 4
D4: 1.2 โครงสร้างและบทบาทหน้าที่ | E4: 3 | F4: 4 | G4: 4 | H4: 3.7 | I4: 3.7 | J4: 3.7 | K4: 3.7 | L4: 3.7 | M4: 3
D5: 1.3 บรรยากาศและวัฒนธรรมสนับสนุนการบริหารความเสี่ยง | E5: 4 | F5: 3 | G5: 3 | H5: 3.25 | I5: 3.25 | J5: 3.25 | K5: 3.25 | L5: 3.25 | M5: 4
D6: 1.4 ความมุ่งมั่นต่อค่านิยมองค์กร | E6: 2 | F6: 3 | G6: 3 | H6: 3.25 | I6: 3.25 | J6: 3.25 | K6: 3.25 | L6: 3.25 | M6: 4
D7: 1.5 แรงจูงใจ การพัฒนาและการรักษาบุคลากร | E7: 2 | F7: 4 | G7: 4 | H7: 3.4 | I7: 3.4 | J7: 3.4 | K7: 3.4 | L7: 3.4 | M7: 3.5
D8: รวม | E8: =SUM(E3:E7) -> 15 | F8: =((F3*$E$3)+(F4*$E$4)+(F5*$E$5)+(F6*$E$6)+(F7*$E$7))/$E$8 -> 2.9333333 | G8: =((G3*$E$3)+(G4*$E$4)+(G5*$E$5)+(G6*$E$6)+(G7*$E$7))/$E$8 -> 3.3333333 | H8: =((H3*$E$3)+(H4*$E$4)+(H5*$E$5)+(H6*$E$6)+(H7*$E$7))/$E$8 -> 3.3866667 | I8: =((I3*$E$3)+(I4*$E$4)+(I5*$E$5)+(I6*$E$6)+(I7*$E$7))/$E$8 -> 3.3866667 | J8: =((J3*$E$3)+(J4*$E$4)+(J5*$E$5)+(J6*$E$6)+(J7*$E$7))/$E$8 -> 3.3866667 | K8: =((K3*$E$3)+(K4*$E$4)+(K5*$E$5)+(K6*$E$6)+(K7*$E$7))/$E$8 -> 3.3866667 | L8: =((L3*$E$3)+(L4*$E$4)+(L5*$E$5)+(L6*$E$6)+(L7*$E$7))/$E$8 -> 3.3866667 | M8: =((M3*$E$3)+(M4*$E$4)+(M5*$E$5)+(M6*$E$6)+(M7*$E$7))/$E$8 -> 3.7333333 | N8: 3.7333 | O8: =((O3*$E$3)+(O4*$E$4)+(O5*$E$5)+(O6*$E$6)+(O7*$E$7))/$E$8 -> 0 | P8: =((P3*$E$3)+(P4*$E$4)+(P5*$E$5)+(P6*$E$6)+(P7*$E$7))/$E$8 -> 0
C9: 2. การกำหนดยุทธศาสตร์ และวัตถุประสงค์/เป้าประสงค์เชิงยุทธศาสตร์ (น้ำหนักร้อยละ 15) | D9: 2.1 การวิเคราะห์ธุรกิจ | E9: 0 | F9: 0
D10: 2.2 การระบุเป้าหมายการบริหารความเสี่ยง | E10: 5 | F10: 4 | G10: 4 | H10: 3 | I10: 3 | J10: 3 | K10: 3 | L10: 3 | M10: 4
D11: 2.3 การประเมินทางเลือกและกำหนดยุทธศาสตร์ | E11: 0 | F11: 0
D12: 2.4 การกำหนดวัตถุประสงค์ในการดำเนินธุรกิจเพื่อสร้างมูลค่าเพิ่มให้กับองค์กร | E12: 10 | F12: 3.5 | G12: 3.5 | H12: 2.5 | I12: 2.5 | J12: 2.5 | K12: 2.5 | L12: 2.5 | M12: 2
D13: รวม | E13: =SUM(E9:E12) -> 15 | F13: =((F9*$E$9)+(F10*$E$10)+(F11*$E$11)+(F12*$E$12))/$E$13 -> 3.6666667 | G13: =((G9*$E$9)+(G10*$E$10)+(G11*$E$11)+(G12*$E$12))/$E$13 -> 3.6666667 | H13: =((H9*$E$9)+(H10*$E$10)+(H11*$E$11)+(H12*$E$12))/$E$13 -> 2.6666667 | I13: =((I9*$E$9)+(I10*$E$10)+(I11*$E$11)+(I12*$E$12))/$E$13 -> 2.6666667 | J13: =((J9*$E$9)+(J10*$E$10)+(J11*$E$11)+(J12*$E$12))/$E$13 -> 2.6666667 | K13: =((K9*$E$9)+(K10*$E$10)+(K11*$E$11)+(K12*$E$12))/$E$13 -> 2.6666667 | L13: =((L9*$E$9)+(L10*$E$10)+(L11*$E$11)+(L12*$E$12))/$E$13 -> 2.6666667 | M13: =((M9*$E$9)+(M10*$E$10)+(M11*$E$11)+(M12*$E$12))/$E$13 -> 2.6666667 | N13: 3.3333 | O13: =((O9*$E$9)+(O10*$E$10)+(O11*$E$11)+(O12*$E$12))/$E$13 -> 0 | P13: =((P9*$E$9)+(P10*$E$10)+(P11*$E$11)+(P12*$E$12))/$E$13 -> 0
C14: 3. กระบวนการบริหารความเสี่ยง (น้ำหนักร้อยละ 35) | D14: 3.1 การระบุปัจจัยเสี่ยง | E14: 5 | F14: 4 | G14: 4 | H14: 3.51 | I14: 3.51 | J14: 3.51 | K14: 3.51 | L14: 3.51 | M14: 4
D15: 3.2 การกำหนดกิจกรรมการควบคุมที่ตอบสนองต่อความเสี่ยงองค์กร | E15: 5 | F15: 4.25 | G15: 4.25 | H15: 3.51 | I15: 3.51 | J15: 3.51 | K15: 3.51 | L15: 3.51 | M15: 4
D16: 3.3 การประเมินระดับความรุนแรงของปัจจัยเสี่ยง | E16: 5 | F16: 4 | G16: 4 | H16: 3.51 | I16: 3.51 | J16: 3.51 | K16: 3.51 | L16: 3.51 | M16: 4
D17: 3.4 การจัดลำดับความเสี่ยง | E17: 3 | F17: 4 | G17: 4 | H17: 3.52 | I17: 3.52 | J17: 3.52 | K17: 3.52 | L17: 3.52 | M17: 4
D18: 3.5 การกำหนด/คัดเลือกวิธีการจัดการต่อความเสี่ยงที่ระบุไว้ | E18: 5 | F18: 4 | G18: 4 | H18: 3.51 | I18: 3.51 | J18: 3.51 | K18: 3.51 | L18: 3.51 | M18: 4
D19: 3.6 การบริหารความเสี่ยงแบบบูรณาการ Risk Correlation Map และการจัดทำ Portfolio View of Risk | E19: 12 | F19: 4 | G19: 4 | H19: 3.52 | I19: 3.52 | J19: 3.52 | K19: 3.52 | L19: 3.52 | M19: 3
D20: รวม | E20: =SUM(E14:E19) -> 35 | F20: =((F14*$E$14)+(F15*$E$15)+(F16*$E$16)+(F17*$E$17)+(F18*$E$18)+(F19*$E$19))/$E$20 -> 4.0357143 | G20: =((G14*$E$14)+(G15*$E$15)+(G16*$E$16)+(G17*$E$17)+(G18*$E$18)+(G19*$E$19))/$E$20 -> 4.0357143 | H20: =((H14*$E$14)+(H15*$E$15)+(H16*$E$16)+(H17*$E$17)+(H18*$E$18)+(H19*$E$19))/$E$20 -> 3.5142857 | I20: =((I14*$E$14)+(I15*$E$15)+(I16*$E$16)+(I17*$E$17)+(I18*$E$18)+(I19*$E$19))/$E$20 -> 3.5142857 | J20: =((J14*$E$14)+(J15*$E$15)+(J16*$E$16)+(J17*$E$17)+(J18*$E$18)+(J19*$E$19))/$E$20 -> 3.5142857 | K20: =((K14*$E$14)+(K15*$E$15)+(K16*$E$16)+(K17*$E$17)+(K18*$E$18)+(K19*$E$19))/$E$20 -> 3.5142857 | L20: =((L14*$E$14)+(L15*$E$15)+(L16*$E$16)+(L17*$E$17)+(L18*$E$18)+(L19*$E$19))/$E$20 -> 3.5142857 | M20: =((M14*$E$14)+(M15*$E$15)+(M16*$E$16)+(M17*$E$17)+(M18*$E$18)+(M19*$E$19))/$E$20 -> 3.6571429 | N20: 3.8571 | O20: =((O14*$E$14)+(O15*$E$15)+(O16*$E$16)+(O17*$E$17)+(O18*$E$18)+(O19*$E$19))/$E$20 -> 0 | P20: =((P14*$E$14)+(P15*$E$15)+(P16*$E$16)+(P17*$E$17)+(P18*$E$18)+(P19*$E$19))/$E$20 -> 0
C21: 4. การทบทวนการบริหารความเสี่ยง (น้ำหนักร้อยละ 15) | D21: 4.1 การทบทวนและปรับปรุงผลการบริหารความเสี่ยง | E21: 10 | F21: 4 | G21: 4 | H21: 2.3 | I21: 2.3 | J21: 2.3 | K21: 2.3 | L21: 2.3 | M21: 3
D22: 4.2 การกำหนดแนวทางในการปรับปรุงกระบวนการบริหารความเสี่ยง | E22: 5 | F22: 3 | G22: 3 | H22: 2.4 | I22: 2.4 | J22: 2.4 | K22: 2.4 | L22: 2.4 | M22: 2
D23: 4.3 การประเมินการเปลี่ยนแปลงที่มีนัยสำคัญ | E23: 0 | F23: 0
D24: รวม | E24: =SUM(E21:E23) -> 15 | F24: =((F21*$E$21)+(F22*$E$22)+(F23*$E$23))/$E$24 -> 3.6666667 | G24: =((G21*$E$21)+(G22*$E$22)+(G23*$E$23))/$E$24 -> 3.6666667 | H24: =((H21*$E$21)+(H22*$E$22)+(H23*$E$23))/$E$24 -> 2.3333333 | I24: =((I21*$E$21)+(I22*$E$22)+(I23*$E$23))/$E$24 -> 2.3333333 | J24: =((J21*$E$21)+(J22*$E$22)+(J23*$E$23))/$E$24 -> 2.3333333 | K24: =((K21*$E$21)+(K22*$E$22)+(K23*$E$23))/$E$24 -> 2.3333333 | L24: =((L21*$E$21)+(L22*$E$22)+(L23*$E$23))/$E$24 -> 2.3333333 | M24: =((M21*$E$21)+(M22*$E$22)+(M23*$E$23))/$E$24 -> 2.6666667 | N24: 3.3333 | O24: =((O21*$E$21)+(O22*$E$22)+(O23*$E$23))/$E$24 -> 0 | P24: =((P21*$E$21)+(P22*$E$22)+(P23*$E$23))/$E$24 -> 0
C25: 5. ข้อมูลสารสนเทศการสื่อสาร และการรายงานผล (น้ำหนักร้อยละ 20) | D25: 5.1 การสื่อสารการบริหารความเสี่ยงองค์กร | E25: 5 | F25: 3 | G25: 3.5 | H25: 3.5 | I25: 3.5 | J25: 3.5 | K25: 3.5 | L25: 3.5 | M25: 3.8 | P25: 4
D26: 5.2 การติดตาม ประเมินผลและรายงานผลการบริหารความเสี่ยง การควบคุมภายใน วัฒนธรรมและผลการดำเนินงาน | E26: 5 | F26: 4 | G26: 3.5 | H26: 3.5 | I26: 3.5 | J26: 3.5 | K26: 3.5 | L26: 3.5 | M26: 3.8 | P26: 4
D27: 5.3 ข้อมูลและเทคโนโลยีในการสนับสนุนการบริหารความเสี่ยง | E27: 6 | F27: 4 | G27: 4 | H27: 3.5 | I27: 3.5 | J27: 3.5 | K27: 3.5 | L27: 3.5 | M27: 3.5 | P27: 3.3
D28: 5.4 กระบวนการบริหารความต่อเนื่องทางธุรกิจ | E28: 4 | F28: 4.25 | G28: 4 | H28: 3.5 | I28: 3.5 | J28: 3.5 | K28: 3.5 | L28: 3.5 | M28: 3.5 | P28: 3.3
D29: รวม | E29: =SUM(E25:E28) -> 20 | F29: =((F25*$E$25)+(F26*$E$26)+(F27*$E$27)+(F28*$E$28))/$E$29 -> 3.8 | G29: =((G25*$E$25)+(G26*$E$26)+(G27*$E$27)+(G28*$E$28))/$E$29 -> 3.75 | H29: =((H25*$E$25)+(H26*$E$26)+(H27*$E$27)+(H28*$E$28))/$E$29 -> 3.5 | I29: =((I25*$E$25)+(I26*$E$26)+(I27*$E$27)+(I28*$E$28))/$E$29 -> 3.5 | J29: =((J25*$E$25)+(J26*$E$26)+(J27*$E$27)+(J28*$E$28))/$E$29 -> 3.5 | K29: =((K25*$E$25)+(K26*$E$26)+(K27*$E$27)+(K28*$E$28))/$E$29 -> 3.5 | L29: =((L25*$E$25)+(L26*$E$26)+(L27*$E$27)+(L28*$E$28))/$E$29 -> 3.5 | M29: =((M25*$E$25)+(M26*$E$26)+(M27*$E$27)+(M28*$E$28))/$E$29 -> 3.65 | N29: 4.0625 | O29: =((O25*$E$25)+(O26*$E$26)+(O27*$E$27)+(O28*$E$28))/$E$29 -> 0 | P29: =((P25*$E$25)+(P26*$E$26)+(P27*$E$27)+(P28*$E$28))/$E$29 -> 3.65
D30: ประมาณการคะแนน | E30: =E8+E13+E20+E24+E29 -> 100 | F30: =((F8*$E$8)+(F13*$E$13)+(F20*$E$20)+(F24*$E$24)+(F29*$E$29))/100 -> 3.7125 | G30: =((G8*$E$8)+(G13*$E$13)+(G20*$E$20)+(G24*$E$24)+(G29*$E$29))/100 -> 3.7625 | H30: =((H8*$E$8)+(H13*$E$13)+(H20*$E$20)+(H24*$E$24)+(H29*$E$29))/100 -> 3.188 | I30: =((I8*$E$8)+(I13*$E$13)+(I20*$E$20)+(I24*$E$24)+(I29*$E$29))/100 -> 3.188 | J30: =((J8*$E$8)+(J13*$E$13)+(J20*$E$20)+(J24*$E$24)+(J29*$E$29))/100 -> 3.188 | K30: =((K8*$E$8)+(K13*$E$13)+(K20*$E$20)+(K24*$E$24)+(K29*$E$29))/100 -> 3.188 | L30: =((L8*$E$8)+(L13*$E$13)+(L20*$E$20)+(L24*$E$24)+(L29*$E$29))/100 -> 3.188 | M30: =((M8*$E$8)+(M13*$E$13)+(M20*$E$20)+(M24*$E$24)+(M29*$E$29))/100 -> 3.37 | ... P30: =((P8*$E$8)+(P13*$E$13)+(P20*$E$20)+(P24*$E$24)+(P29*$E$29))/100 -> 0.73
H31: % Diff จากปีที่ผ่านมา | I31: =(I30-B30)/B30 -> #DIV/0! | J31: =(J30-I30)/I30 -> 0 | K31: =(K30-J30)/J30 -> 0 | L31: =(L30-K30)/K30 -> 0 | M31: =(M30-H30)/H30 -> 0.057089084 | N31: =(N30-M30)/M30 -> 0.1045905 | O31: =(O30-N30)/N30 -> -1 | P31: =(P30-O30)/O30 -> #DIV/0!
H32: เป้าหมายของคะแนน | I32: 4 | J32: 4 | K32: 4.25 | L32: 4.5 | M32: 4 | N32: 4 | O32: 4.25 | P32: 4.5 | Q32: เป้าหมายแต่ละปีขึ้นอยากับการตกลงร่วมกันกับ Process Owner
L34: =(M30-K30)/M30 -> 0.054005935

Sheet RM&IC_OFI Improvement Plan
A1: Topic | B1: Wt. | C1: Sub-Topic | D1: Wt. | E1: OFI Year (ปีที่พบ OFI) | F1: คะแนนจาก สคร. | G1: แหล่งที่มาของ Improvement Plan | H1: OFI | I1: Element Owner ชื่อและรูป ผู้บริหาร | J1: หน่วยงานหลักที่รับผิดชอบ (ฝ่าย) | K1: หน่วยงานรองที่รับผิดชอบ (ฝ่าย) | L1: OFI level | M1: Type of OFI | N1: Issue of OFI | O1: Using L5 Template | P1: แผนการปรับปรุง OFI | Q1: ร่วมทำแผนปรับปรุง OFI กับ Process Owner (พ.ค. - มิ.ย.) | R1: รายงาน EO และ EC พร้อม SE-AM Score (มิ.ย. - ก.ค.) | S1: รายงานพร้อมผล SE-AM Assessment (ต.ค. - พ.ย.) | T1: ก่อนนำเอกสารเข้าระบบ (ธ.ค.) | U1: รายงานเตรียม Site Visit (ม.ค.)
A2: 1. ธรรมาภิบาลและวัฒนธรรมองค์กร | B2: 0.15 | C2: 1.1 บทบาทคณะกรรมการในการกำกับติดตามการบริหารความเสี่ยงและการพัฒนาระบบการควบคุมภายใน | D2: 0.04 | E2: 2568 | F2: ='ประมาณการคะแนน หัวข้อ RM&IC'!N8 -> 3.7333 | G2: สคร. | H2: ยังไม่ชัดเจนว่าจากข้อมูลนําเข้าต่างๆ ส่งผลต่อการทบทวนนโยบาย GRC อย่างไร ควรแสดงให้เห็นแนวทางการนําข้อมูลนําเข้าและผลวิเคราะห์ที่นํามาใช้ในการทบทวนนโยบาย GRC ให้ชัดเจนขึ้น | I2: นายฐานันท์ จิตต์บุญ | J2: กธญ. | L2: L4 | M2: Process | N2: #GRCPolicy | O2: Yes / No | P2: Link ไปหาไฟล์ PPTX, PDF | Q2: Done | R2: In Progress | S2: In Progress | T2: In Progress | U2: In Progress
C3: 1.1 บทบาทคณะกรรมการในการกำกับติดตามการบริหารความเสี่ยงและการพัฒนาระบบการควบคุมภายใน | D3: 0.04 | E3: 2568 | G3: สคร. | H3: ควรพัฒนาระบบ GRC ให้เชื่อมโยงกับระบบอื่นๆ เพิ่มเติม เพื่อเพิ่มประสิทธิภาพให้ดียิ่งขึ้น | I3: นายฐานันท์ จิตต์บุญ น.ส.เมธ์ลดา ชยวัฒนางกูร | J3: กธญ. | K3: งสญ. ภสญ. | L3: หมายเหตุ | M3: Process | N3: #GRCIntegration | O3: Yes / No | Q3: Done | R3: In Progress | S3: In Progress | T3: In Progress | U3: In Progress
D4: 0.04 | E4: 2567 | F4: ='ประมาณการคะแนน หัวข้อ RM&IC'!H8 -> 3.3866667 | G4: SE-AM Assessment | H4: จากการตรวจประเมิน ไม่พบการนำประเด็นความเชื่อมโยงนโยบาย GRC กับนโยบายอื่นๆ มาเป็นปัจจัยในการทบทวน รวมทั้งผลลัพธ์จากการทบทวนเพื่อมั่นใจได้ว่านโยบาย GRC สอดคล้องกับนโยบายอื่นๆที่เกี่ยวข้อง (เช่น Digital, Customer, Stakeholder, Innovation Policy etc.) กธญ. | I4: ชื่อและรูป ผู้บริหาร | J4: บสญ. | L4: L3 | M4: Result | N4: #3YearsResult | O4: Yes | U4: Qualified
D5: 0.04 | E5: 2567 | G5: SE-AM Assessment | H5: จากการตรวจประเมินพบว่ามีการพิจารณาปัจจัยนำเข้าที่เกี่ยวข้องในการปรับปรุง เช่น การนำประเด็นวิสัยทัศน์ของ ปตท. ที่มีการเปลี่ยนแปลงเข้ามาพิจารณา ทั้งนี้ยังไม่พบผลลัพธ์หรือการประเมินประสิทธิผลของการปรับปรุงนโยบาย GRC เพื่อสะท้อนผลการดำเนินงานที่ดีขึ้น กธญ. | I5: ชื่อและรูป ผู้บริหาร | J5: บสญ. | L5: L4 | M5: Result | N5: #StrategicPositioning | O5: No
C6: 1.2 โครงสร้างและบทบาทหน้าที่ | D6: 0.03 | E6: 2568 | G6: สคร. | H6: การประเมินประสิทธิผลการกําหนดโครงสร้าง&บทบาทหน้าที่ ยังไม่สะท้อนถึงการประเมินผลในเชิงกระบวนการ ยังเป็นการวัดผลลัพธ์ (Output) ของการดําเนินงานตามโครงสร้างที่ได้วางไว้ | I6: นายฐานันท์ จิตต์บุญ น.ส.เมธ์ลดา ชยวัฒนางกูร | J6: พอญ. ลขญ .กธญ. งสญ. ภสญ. กมญ. | L6: L5 | M6: Result | N6: #GRCOrganization #OutputPI | O6: Yes / No | Q6: Done | R6: In Progress | S6: In Progress | T6: In Progress | U6: In Progress
D7: 0.03 | E7: 2567 | G7: SE-AM Assessment | H7: จากการตรวจประเมินพบว่ามีกระบวนการตรวจสอบถึงความเข้าใจของผู้บริหารและพนักงานในการสำรวจความเข้าใจผ่าน GRC Survey รวมทั้งมีการบูรณาการคำถามใน GRC Survey ที่สอดคล้องกับคู่มือการบริหารความเสี่ยงและการควบคุมภายใน และมีการวิเคราะห์ผลลัพธ์จากการสำรวจฯดังกล่าว ทั้งนี้เพื่อความครบถ้วนตามเกณฑ์ยังไม่พบผลลัพธ์บรรลุเป้าหมายตามแผนได้ครบถ้วน (GRC ได้กำหนดเป้าหมาย ปี 2567 ไว้ที่ 95% ซึ่งผลการประเมิน GRC Survey 2024 ในภาพรวม = 92.09%) กธญ.
D8: 0.03 | E8: 2567 | G8: SE-AM Assessment | H8: จากการตรวจประเมินพบว่ามีการปรับปรุงกระบวนการกำหนดโครงสร้างบทบาทหน้าที่ เช่น การปรับปรุงโครงการ Risk Owner ดีเด่น (2566 และ 2567) เพื่อเป็นการส่งเสริมความสำคัญ และสร้าง engagement ยกย่องชมเชยพนักงานที่ได้ให้ความร่วมมือด้านการบริหารความเสี่ยงและควบคุมภายในและทำให้การประเมินฯเป็นไปอย่างมีประสิทธิภาพ ทั้งนี้ยังไม่พบหลักฐานชัดเจนที่แสดงถึงผลลัพธ์เกี่ยวกับจำนวน Risk Owner ณ ปีปัจจุบันเพื่อสะท้อนให้เห็นถึงผลจากการปรับปรุงนำไปสู่แรงจูงใจที่เพิ่มขึ้น ส่งให้ผลให้มี Risk Owner ดีเด่นเพิ่มขึ้นหรือลดลงอย่างไร รวมทั้งผลลัพธ์จากการปรับปรุงดังกล่าวสะท้อนให้เห็นถึงผลการบริหารความเสี่ยงบรรลุตามเป้าหมาย ภสญ.
D9: 0.03 | E9: 2567 | G9: สคร. | H9: ควรทบทวนเกณฑ์การประเมินประสิทธิผลของการกำหนดโครงสร้างและบทบาทหน้าที่ให้สะท้อนถึงการประเมินผลในเชิงกระบวนการ
C10: 1.3 บรรยากาศและวัฒนธรรมสนับสนุนการบริหารความเสี่ยง | D10: 0.04 | E10: 2568 | G10: สคร. | H10: คะแนนประเมินด้าน CG & Compliance ในกลุ่มผู้บริหาร & พนักงานมีผลที่ลดลงกว่าปีก่อนหน้า จึงควรพัฒนา ปรับปรุงการสร้างความรู้ ความเข้าใจให้ดียิ่งขึ้นในปีถัดไป | I10: นายฐานันท์ จิตต์บุญ | J10: กธญ. กมญ. | L10: L5 | M10: Process | N10: #GRCSurvey | O10: Yes / No | Q10: Done | R10: In Progress | S10: In Progress | T10: In Progress | U10: In Progress
D11: 0.04 | E11: 2567 | G11: คาดการณ์จากคำถาม Bridge Consulting | H11: การสร้างบรรยากาศและวัฒนธรรมสนับสนุนการบริหารความเสี่ยง ที่ระบุอยู่ในแผน HR และ IT กทญ.
C12: 1.4 ความมุ่งมั่นต่อค่านิยมองค์กร | D12: 0.02 | E12: 2568 | G12: สคร. | H12: คะแนนประเมินด้าน CG & Compliance ในกลุ่มผู้บริหาร & พนักงานมีผลที่ลดลงกว่าปีก่อนหน้า จึงควรพัฒนา ปรับปรุงการสร้างความรู้ ความเข้าใจให้ดียิ่งขึ้นในปีถัดไป | I12: นายฐานันท์ จิตต์บุญ | J12: กธญ. กมญ. | L12: L5 | M12: Process | N12: #GRCSurvey | O12: Yes / No | Q12: Done | R12: In Progress | S12: In Progress | T12: In Progress | U12: In Progress
D13: 0.02 | E13: 2567 | G13: คาดการณ์จากคำถาม Bridge Consulting | H13: การสร้างบรรยากาศและวัฒนธรรมสนับสนุนการบริหารความเสี่ยง ที่ระบุอยู่ในแผน HR และ IT กทญ.
C14: 1.5 แรงจูงใจ การพัฒนาและการรักษาบุคลากร | D14: 0.02 | E14: 2568 | G14: สคร. | H14: ควรพิจารณาทบทวนเกณฑ์การประเมินให้สะท้อนการวัดประสิทธิผลของกระบวนการเชื่อมโยงระหว่างการบริหารความเสี่ยง & ผลตอบแทน/แรงจูงใจ | I14: น.ส.เมธ์ลดา ชยวัฒนางกูร | J14: งสญ. กธญ. ภสญ. | K14: นทญ. | L14: L5 | M14: Result | N14: #OutputPI #OutcomePI #GRCIncentive | O14: Yes / No | Q14: Done | R14: In Progress | S14: In Progress | T14: In Progress | U14: In Progress
D15: 0.02 | E15: 2567 | G15: สคร. | H15: ควรพิจารณาทบทวนแนวทางในการเชื่อมโยงผลการประเมินการบริหารความเสี่ยงกับผลตอบแทนและแรงจูงใจให้มีความชัดเจน และเป็นรูปธรรมมากยิ่งขึ้น
A16: 2. การกำหนดยุทธศาสตร์ และวัตถุประสงค์/เป้าประสงค์เชิงยุทธศาสตร์ | B16: 0.15 | C16: 2.1 การวิเคราะห์ธุรกิจ | D16: 0 | E16: 2568 | F16: ='ประมาณการคะแนน หัวข้อ RM&IC'!N13 -> 3.3333
B17: 0.15 | C17: 2.1 การวิเคราะห์ธุรกิจ | D17: 0 | E17: 2567 | F17: ='ประมาณการคะแนน หัวข้อ RM&IC'!H13 -> 2.6666667
C18: 2.2 การระบุเป้าหมายการบริหารความเสี่ยง | D18: 0.05 | E18: 2567 | G18: SE-AM Assessment | H18: จากการตรวจประเมินยังไม่พบหลักฐานชัดเจนที่แสดงถึง ผลการประเมินประสิทธิผลของการกำหนดค่า RA RT หลังการทบทวนแผนบริหารความเสี่ยงองค์กรระหว่างปี และนำข้อมูลไปใช้เพื่อปรับปรุงกระบวนการฯ เพื่อสะท้อนผลการดำเนินงานที่ดีขึ้น งสญ.
C19: 2.3 การประเมินทางเลือกและกำหนดยุทธศาสตร์ | D19: 0 | E19: 2567
C20: 2.4 การกำหนดวัตถุประสงค์ในการดำเนินธุรกิจเพื่อสร้างมูลค่าเพิ่มให้กับองค์กร | D20: 0.1 | E20: 2568 | G20: สคร. | H20: ควรพิจารณาปรับปรุงแนวทาง การกําหนดค่าเป้าหมายในการบริหารความเสี่ยงให้สมเหตุสมผล หากเป็นปัจจัยเสี่ยงที่ต้องบริหารในระยะยาว ควรปรับค่าเป้าหมายการบริหารความเสี่ยงให้เหมาะสมกับการดําเนินงานในแต่ละช่วงเวลา เพื่อให้สามารถบริหารจัดการและสะท้อนผลการบริหารความเสี่ยงได้ชัดเจนยิ่งขึ้น | I20: น.ส.เมธ์ลดา ชยวัฒนางกูร | J20: งสญ. | L20: L3 | M20: Process | N20: #KRI | O20: Yes / No | R20: In Progress | S20: In Progress | T20: In Progress | U20: In Progress
D21: 0.1 | E21: 2567 | G21: SE-AM Assessment | H21: จากการตรวจประเมินพบว่ามีกระบวนการในการทำ Value Creation และ Value Enhancement เพื่อให้เชื่อมโยงกับวัตถุประสงค์เชิงยุทธศาสตร์ (New Business) มีการคาดการณ์ผลลัพธ์การลดระดับความเสี่ยง(Estimate) ถึงระดับความรุนแรงของปัจจัยเสี่ยงที่ลดลง ทั้งนี้เพื่อความครบถ้วนและการมุ่งเน้นผลลัพธ์ ควรแสดงให้เห็นการลดระดับความรุนแรงของปัจจัยเสี่ยงที่เกิดขึ้นจริง และได้ตามเป้าหมายทุกๆความเสี่ยง ส่งผลในการสร้างความมั่นใจถึงการสร้างมูลค่าเพิ่มให้กับองค์กรได้ตามเป้าหมายที่กำหนด งสญ.
D22: 0.1 | E22: 2567 | G22: SE-AM Assessment | H22: ตามที่มีการปรับแผนบริหารความเสี่ยง (New Business) ควรแสดงให้เห็นถึงการวิเคราะห์และทบทวนแผนแม่บทที่เกี่ยวข้อง เช่น แผนงาน KM เป็นต้น งสญ.
D23: 0.1 | E23: 2567 | G23: SE-AM Assessment | H23: จากการตรวจประเมินยังไม่พบหลักฐานชัดเจนที่แสดงถึงการประเมินประสิทธิผลของการทำ Value Creation และ Value Enhancement ในการนำมาบริหารและสร้างมูลค่าเพิ่มให้กับองค์กร และนำข้อมูลไปใช้เพื่อปรับปรุงกระบวนการฯ เพื่อสะท้อนผลการดำเนินงานที่ดีขึ้น งสญ.
D24: 0.1 | G24: สคร. | H24: ปตท. มีระดับความรุนแรงของความเสี่ยงที่ไม่สามารถบริหารได้ตามเป้าหมาย ได้แก่ Project Execution 5th NG Pipeline Phase 2 และ GSP#7 แต่ทั้ง 2 ปัจจัยเสี่ยงไม่ส่งผลกระทบต่อ ปตท.
A25: 3. กระบวนการบริหารความเสี่ยง | B25: 0.35 | C25: 3.1 การระบุปัจจัยเสี่ยง | D25: 0.05 | E25: 2568 | F25: ='ประมาณการคะแนน หัวข้อ RM&IC'!N20 -> 3.8571 | O25: Yes / No | R25: In Progress | S25: In Progress | T25: In Progress | U25: In Progress
E26: 2567 | F26: ='ประมาณการคะแนน หัวข้อ RM&IC'!H20 -> 3.5142857 | G26: SE-AM Assessment | H26: จากการตรวจประเมิน ยังไม่พบหลักฐานชัดเจนที่แสดงถึงผลลัพธ์จากการประเมินประสิทธิผลของการปรับปรุงกระบวนการระบุปัจจัยเสี่ยง เพื่อสะท้อนให้เห็นถึงผลการดำเนินงานที่ดีขึ้น งสญ.
D27: 0.05 | G27: สคร. | H27: ควรพิจารณาทบทวนเกณฑ์การประเมินประสิทธิผลให้สะท้อนถึงคุณภาพของการระบุความเสี่ยงระดับองค์กรให้ชัดเจนยิ่งขึ้น
C28: 3.2 การกำหนดกิจกรรมการควบคุมที่ตอบสนองต่อความเสี่ยงองค์กร | D28: 0.05 | E28: 2567 | G28: SE-AM Assessment | H28: จากการตรวจประเมินพบว่าทุกสายงานมีการประเมินกิจกรรมการควบคุมประกอบการวิเคราะห์ปัจจัยเสี่ยงระดับสายงาน ผ่านกระบวนการประเมินโดยระบบ Risk and Control Platform (ระบบ RCP) ทั้งนี้เพื่อความครบถ้วนสมบูรณ์ ควรแสดงหลักฐานถึงการวิเคราะห์สรุปผล คะแนนประเมินการควบคุมภายใน คะแนนประเมินฯ ตามองค์ประกอบการควบคุมภายใน รายงานสรุปผลการดำเนินงานกิจกรรมควบคุมที่เป็น Action Plan เพื่อให้มั่นใจได้ว่ามีการประเมินประสิทธิผลของทุกขั้นตอน และทุกขั้นตอนได้ประสิทธิผลตามที่กำหนด (ตามที่เกณฑ์ระดับ 3 ระบุ) ภสญ.
D29: 0.05 | E29: 2567 | G29: SE-AM Assessment | H29: จากการตรวจประเมิน มีการทบทวนกิจกรรมการควบคุมระหว่างปี เพื่อให้กิจกรรมการควบคุมเป็นส่วนหนึ่งของแผนงานจัดการความเสี่ยง ทั้งนี้ยังไม่พบหลักฐานชัดเจนที่แสดงถึงผลลัพธ์จากการประเมินประสิทธิผลของการทบทวน/ปรับปรุงกิจกรรมควบคุมระหว่างปี เพื่อสะท้อนให้เห็นถึงผลการดำเนินงานที่ดีขึ้น สนับสนุนให้ความเสี่ยงบรรลุตามเป้าหมายที่กำหนด งสญ. | P29: Average | Q29: =AVERAGE(Q2:Q28) -> #DIV/0! | R29: =AVERAGE(R2:R28) -> #DIV/0! | S29: =AVERAGE(S2:S28) -> #DIV/0!
D30: 0.05 | G30: สคร. | H30: จากผลบริหารความเสี่ยงปี 67 มี 2 ปัจจัยเสี่ยงที่ระดับความรุนแรงไม่เป็นไปตามเป้าหมาย - พิจารณาทบทวนกิจกรรมควบคุมระหว่างปีให้มีประสิทธิภาพมากขึ้น
C31: 3.3 การประเมินระดับความรุนแรงของปัจจัยเสี่ยง | D31: 0.05 | E31: 2567 | G31: SE-AM Assessment | H31: จากการตรวจประเมินยังไม่พบหลักฐานชัดเจนที่แสดงถึงผลลัพธ์จากการประเมินประสิทธิผลของการกำหนดเกณฑ์ประเมินระดับความรุนแรง ทั้งในเชิงโอกาส และผลกระทบและนำข้อมูลไปใช้เพื่อปรับปรุงกระบวนการฯเพื่อสะท้อนให้เห็นถึงผลการดำเนินงานที่ดีขึ้น งสญ.
D32: 0.05 | G32: สคร. | H32: ปตท. มีเกณฑ์การประเมินประสิทธิผลของกระบวนการต่างๆ ที่ปัจจุบันยังไม่สะท้อนถึงการวัดผลในเชิงกระบวนการ แต่เป็นการวัดผลลัพธ์ (Output) ทำให้ยังไม่สามาถนำข้อมูลผลการประเมินไปใช้ปรับปรุงกระบวนการได้อย่างชัดเจน
C33: 3.4 การจัดลำดับความเสี่ยง | D33: 0.03 | E33: 2567 | G33: SE-AM Assessment | H33: จากการตรวจประเมินยังไม่พบหลักฐานชัดเจนที่แสดงถึงผลลัพธ์การประเมินประสิทธิผลของการการกำหนดขอบเขตระดับความเสี่ยงที่องค์กรสามารถรับได้ (Risk Boundary) และการจัดลำดับความเสี่ยง ของแต่ละปัจจัยเสี่ยง และการจัดทำแผนภาพความเสี่ยง (Risk Profile) (ทุกขั้นตอนได้ประสิทธิผลตามที่กำหนด: ความครบถ้วนของปัจจัย, กระบวนการ, ผลผลิต, ระยะเวลาที่แล้วเสร็จ) และนำข้อมูลไปใช้เพื่อปรับปรุงกระบวนการฯ เพื่อสะท้อนให้เห็นถึงผลการดำเนินงานที่ดีขึ้น งสญ.
D34: 0.03 | G34: สคร. | H34: ปตท. มีเกณฑ์การประเมินประสิทธิผลของกระบวนการต่างๆ ที่ปัจจุบันยังไม่สะท้อนถึงการวัดผลในเชิงกระบวนการ แต่เป็นการวัดผลลัพธ์ (Output) ทำให้ยังไม่สามาถนำข้อมูลผลการประเมินไปใช้ปรับปรุงกระบวนการได้อย่างชัดเจน
C35: 3.5 การกำหนด/คัดเลือกวิธีการจัดการต่อความเสี่ยงที่ระบุไว้ | D35: 0.05 | E35: 2568 | G35: สคร. | H35: ควรประเมินประสิทธิผลกระบวนการด้วยตัวชี้วัดที่เหมาะสม และนําผลการประเมินไปใช้ในการเปรียบเทียบกับผลการดําเนินงานในปีถัดไป เพื่อให้ทราบถึงความเปลี่ยนแปลง และใช้ข้อมูลในการปรับปรุง และยกระดับการดําเนินงานอย่างต่อเนื่องต่อไป | I35: นายฐานันท์ จิตต์บุญ น.ส.เมธ์ลดา ชยวัฒนางกูร | J35: งสญ. | K35: ภสญ. | L35: L5 | M35: Result | N35: #OutputPI #OutcomePI | O35: Yes / No | R35: In Progress | S35: In Progress | T35: In Progress | U35: In Progress
E36: 2567 | G36: SE-AM Assessment | H36: จากการตรวจประเมินพบว่ามีการบูรณาการ การบริหารความเสี่ยงองค์กรกับกิจกรรมการควบคุมและการออกแบบระบบงาน (Work System) และกระบวนการ (Work Process) เช่น การติดตามแผนงาน Corporate Risk Profile Cyber Resilience ซึ่งได้กำหนดเป็นแผนปฏิบัติการประจำปีของฝ่าย กดม. และเชื่อมโยงกระบวนการ Work Process: Digital Management ทั้งนี้เพื่อให้ครบถ้วนสอดคล้องกับ Corporate Risk Profile ทั้งหมด ควรแสดงให้เห็นถึงความเชื่อมโยงความเสี่ยงองค์กรอื่นๆกับการจัดการต่อความเสี่ยงที่เชื่อมโยงกับการออกแบบระบบงาน (Work System) และกระบวนการ (Work Process) งสญ. พอญ. | N36: #OutcomePI
D37: 0.05 | E37: 2567 | G37: SE-AM Assessment | H37: จากการตรวจประเมินยังไม่พบหลักฐานชัดเจนที่แสดงถึงผลลัพธ์การประเมินประสิทธิผลของการกำหนด/คัดเลือกวิธีการจัดการต่อความเสี่ยง (Mitigation) และนำข้อมูลไปใช้เพื่อปรับปรุงกระบวนการฯ เพื่อสะท้อนให้เห็นถึงผลการดำเนินงานที่ดีขึ้น งสญ.
D38: 0.05 | G38: สคร. | H38: ปตท. มีเกณฑ์การประเมินประสิทธิผลของกระบวนการต่างๆ ที่ปัจจุบันยังไม่สะท้อนถึงการวัดผลในเชิงกระบวนการ แต่เป็นการวัดผลลัพธ์ (Output) ทำให้ยังไม่สามาถนำข้อมูลผลการประเมินไปใช้ปรับปรุงกระบวนการได้อย่างชัดเจน
C39: 3.6 การบริหารความเสี่ยงแบบบูรณาการ Risk Correlation Map และการจัดทำ Portfolio View of Risk | D39: 0.12 | E39: 2568 | G39: สคร. | H39: ควรพิจารณาถึงความสัมพันธ์ สอดคล้องระหว่างค่า RA/RT ของค่าเป้าหมายกับแต่ละ Risk Factors ด้วย | I39: น.ส.เมธ์ลดา ชยวัฒนางกูร | J39: งสญ. | L39: L4 | M39: Process | N39: #RA #RT | O39: Yes / No | R39: In Progress | S39: In Progress | T39: In Progress | U39: In Progress
C40: 3.6 การบริหารความเสี่ยงแบบบูรณาการ Risk Correlation Map และการจัดทำ Portfolio View of Risk | D40: 0.12 | E40: 2568 | G40: สคร. | H40: ยังไม่มีความชัดเจนในการแสดงให้เห็นถึงการวิเคราะห์ภาพรวมของความเสี่ยงที่ยอมรับได้ (RA) ของทุกปัจจัยเสี่ยง (Portfolio View of Risk) ว่ามีความสอดคล้อง เชื่่อมโยงกับเป้าประสงค์ และเป้าหมาย/ตัวชี้วัดที่สําคัญขององค์กร | I40: น.ส.เมธ์ลดา ชยวัฒนางกูร | J40: งสญ. | L40: L4 | M40: Process | N40: #RA #PortfolioViewofRisk | O40: Yes / No | R40: In Progress | S40: In Progress | T40: In Progress | U40: In Progress
...

Sheet คำอธิบายเกณฑ์ Prioritize OFI
A1: การคัดเลือก OFI เพื่อปรับปรุง โดยใช้หลักการ Weighted Scoring Model ซึ่งแต่ละเกณฑ์จะมีน้ำหนัก (Weight) ต่างกันตามความสำคัญ
A2: และแต่ละหัวข้อจะได้รับคะแนนในแต่ละเกณฑ์ จากนั้นนำคะแนนมาคูณกับน้ำหนักเพื่อหาคะแนนรวม
A3: ลำดับที่ | B3: รายการ OFI ทั้งหมด | C3: คะแนนจาก สคร. ในหัวข้อย่อย น้อยกว่า 3 | D3: มี Action Plan รองรับการปิด OFI อยู่แล้ว | E3: 1. น้ำหนักคะแนนตามเกณฑ์รายข้อ | G3: 2. ระดับ OFI ที่ได้รับ | I3: 3. ความง่ายในการแก้ | K3: 4. ผลกระทบต่อความสำเร็จของ Strategic Objective | M3: 5.งบประมาณที่ใช้ | O3: 6. เทคโนโลยีดิจิทัล | Q3: คะแนนรวม | R3: มีนโยบายหรือมีมติจากฝ่ายบริหารให้ปิด OFI เพิ่มเติมหลังการจัดลำดับความสำคัญโดย Process owner
F4: 0.3 | H4: 0.3 | J4: 0.15 | L4: 0.15 | N4: 0.05 | P4: 0.05
A5: 1 | E5: 1-2 | F5: {=_xlfn.IFS( E5="1-2", 1, E5="3-5", 2, E5="6-10", 3, E5="11-15", 4, E5="15 ขึ้นไป", 5, TRUE, "" )} -> 1 | G5: L5 | H5: {=_xlfn.IFS( G5="L5", 1, G5="L4", 2, G5="L3", 5, G5="L2", 5, G5="L1", 5, TRUE, "" )} -> 1 | I5: แก้ทั้งองค์กร | J5: {=_xlfn.IFS( I5="แก้ทั้งองค์กร", 1, I5="แก้ข้ามรอง/ผู้ช่วยขึ้นตรง", 2, I5="ต้องแต่งตั้งคณะทำงานเพื่อแก้ไข OFI", 3, I5="แก้ภายในผู้ช่วยเดียวกัน", 4, I5="แก้ระดับฝ่าย", 5, TRUE, "" )} -> 1 | K5: ไม่มีผลกระทบ / ไม่เกี่ยวข้อง | L5: {=_xlfn.IFS( K5="ไม่มีผลกระทบ / ไม่เกี่ยวข้อง", 1, K5="มีผลกระทบ / เกี่ยวข้อง", 5, TRUE, "" )} -> 1 | M5: มีความจำเป็นต้องขออนุมัติตั้งงบประมาณเพิ่มเติม | N5: {=_xlfn.IFS( M5="มีความจำเป็นต้องขออนุมัติตั้งงบประมาณเพิ่มเติม", 1, M5="สามารถตั้งงบเพียงพอ อยู่ในแผนงาน", 3, M5="ไม่ต้องใช้งบประมาณ", 5, TRUE, "" )} -> 1 | O5: ค่าใช้จ่ายสูงมากกว่า 500000 บาท | P5: {=_xlfn.IFS( O5="ค่าใช้จ่ายสูงมากกว่า 500000 บาท", 1, O5="ผ่านการอนุมัติจากสายงาน", 3, O5="ไม่ต้องใช้เทคโนโลยี", 5, TRUE, "" )} -> 1 | Q5: =SUM(F5*0.3,H5*0.3,J5*0.15,L5*0.15,N5*0.05,P5*0.05) -> 1
A6: 2 | E6: 3-5 | F6: {=_xlfn.IFS( E6="1-2", 1, E6="3-5", 2, E6="6-10", 3, E6="11-15", 4, E6="15 ขึ้นไป", 5, TRUE, "" )} -> 2 | G6: L4 | H6: {=_xlfn.IFS( G6="L5", 1, G6="L4", 2, G6="L3", 5, G6="L2", 5, G6="L1", 5, TRUE, "" )} -> 2 | I6: แก้ข้ามรอง/ผู้ช่วยขึ้นตรง | J6: {=_xlfn.IFS( I6="แก้ทั้งองค์กร", 1, I6="แก้ข้ามรอง/ผู้ช่วยขึ้นตรง", 2, I6="ต้องแต่งตั้งคณะทำงานเพื่อแก้ไข OFI", 3, I6="แก้ภายในผู้ช่วยเดียวกัน", 4, I6="แก้ระดับฝ่าย", 5, TRUE, "" )} -> 2 | K6: ไม่มีผลกระทบ / ไม่เกี่ยวข้อง | L6: {=_xlfn.IFS( K6="ไม่มีผลกระทบ / ไม่เกี่ยวข้อง", 1, K6="มีผลกระทบ / เกี่ยวข้อง", 5, TRUE, "" )} -> 1 | M6: ไม่ต้องใช้งบประมาณ | N6: {=_xlfn.IFS( M6="มีความจำเป็นต้องขออนุมัติตั้งงบประมาณเพิ่มเติม", 1, M6="สามารถตั้งงบเพียงพอ อยู่ในแผนงาน", 3, M6="ไม่ต้องใช้งบประมาณ", 5, TRUE, "" )} -> 5 | O6: ผ่านการอนุมัติจากสายงาน | P6: {=_xlfn.IFS( O6="ค่าใช้จ่ายสูงมากกว่า 500000 บาท", 1, O6="ผ่านการอนุมัติจากสายงาน", 3, O6="ไม่ต้องใช้เทคโนโลยี", 5, TRUE, "" )} -> 3 | Q6: =SUM(F6*0.3,H6*0.3,J6*0.15,L6*0.15,N6*0.05,P6*0.05) -> 2.05
A7: 3 | E7: 6-10 | F7: {=_xlfn.IFS( E7="1-2", 1, E7="3-5", 2, E7="6-10", 3, E7="11-15", 4, E7="15 ขึ้นไป", 5, TRUE, "" )} -> 3 | G7: L3 | H7: {=_xlfn.IFS( G7="L5", 1, G7="L4", 2, G7="L3", 5, G7="L2", 5, G7="L1", 5, TRUE, "" )} -> 5 | I7: แก้ภายในผู้ช่วยเดียวกัน | J7: {=_xlfn.IFS( I7="แก้ทั้งองค์กร", 1, I7="แก้ข้ามรอง/ผู้ช่วยขึ้นตรง", 2, I7="ต้องแต่งตั้งคณะทำงานเพื่อแก้ไข OFI", 3, I7="แก้ภายในผู้ช่วยเดียวกัน", 4, I7="แก้ระดับฝ่าย", 5, TRUE, "" )} -> 4 | L7: {=_xlfn.IFS( K7="ไม่มีผลกระทบ / ไม่เกี่ยวข้อง", 1, K7="มีผลกระทบ / เกี่ยวข้อง", 5, TRUE, "" )} | M7: ไม่ต้องใช้งบประมาณ | N7: {=_xlfn.IFS( M7="มีความจำเป็นต้องขออนุมัติตั้งงบประมาณเพิ่มเติม", 1, M7="สามารถตั้งงบเพียงพอ อยู่ในแผนงาน", 3, M7="ไม่ต้องใช้งบประมาณ", 5, TRUE, "" )} -> 5 | O7: ไม่ต้องใช้เทคโนโลยี | P7: {=_xlfn.IFS( O7="ค่าใช้จ่ายสูงมากกว่า 500000 บาท", 1, O7="ผ่านการอนุมัติจากสายงาน", 3, O7="ไม่ต้องใช้เทคโนโลยี", 5, TRUE, "" )} -> 5 | Q7: =SUM(F7*0.3,H7*0.3,J7*0.15,L7*0.15,N7*0.05,P7*0.05) -> #VALUE!
A8: 4 | E8: 11-15 | F8: {=_xlfn.IFS( E8="1-2", 1, E8="3-5", 2, E8="6-10", 3, E8="11-15", 4, E8="15 ขึ้นไป", 5, TRUE, "" )} -> 4 | G8: L2 | H8: {=_xlfn.IFS( G8="L5", 1, G8="L4", 2, G8="L3", 5, G8="L2", 5, G8="L1", 5, TRUE, "" )} -> 5 | I8: ต้องแต่งตั้งคณะทำงานเพื่อแก้ไข OFI | J8: {=_xlfn.IFS( I8="แก้ทั้งองค์กร", 1, I8="แก้ข้ามรอง/ผู้ช่วยขึ้นตรง", 2, I8="ต้องแต่งตั้งคณะทำงานเพื่อแก้ไข OFI", 3, I8="แก้ภายในผู้ช่วยเดียวกัน", 4, I8="แก้ระดับฝ่าย", 5, TRUE, "" )} -> 3 | L8: {=_xlfn.IFS( K8="ไม่มีผลกระทบ / ไม่เกี่ยวข้อง", 1, K8="มีผลกระทบ / เกี่ยวข้อง", 5, TRUE, "" )} | N8: {=_xlfn.IFS( M8="มีความจำเป็นต้องขออนุมัติตั้งงบประมาณเพิ่มเติม", 1, M8="สามารถตั้งงบเพียงพอ อยู่ในแผนงาน", 3, M8="ไม่ต้องใช้งบประมาณ", 5, TRUE, "" )} | P8: {=_xlfn.IFS( O8="ค่าใช้จ่ายสูงมากกว่า 500000 บาท", 1, O8="ผ่านการอนุมัติจากสายงาน", 3, O8="ไม่ต้องใช้เทคโนโลยี", 5, TRUE, "" )} | Q8: =SUM(F8*0.3,H8*0.3,J8*0.15,L8*0.15,N8*0.05,P8*0.05) -> #VALUE!
A9: 5 | E9: 15 ขึ้นไป | F9: {=_xlfn.IFS( E9="1-2", 1, E9="3-5", 2, E9="6-10", 3, E9="11-15", 4, E9="15 ขึ้นไป", 5, TRUE, "" )} -> 5 | G9: L1 | H9: {=_xlfn.IFS( G9="L5", 1, G9="L4", 2, G9="L3", 5, G9="L2", 5, G9="L1", 5, TRUE, "" )} -> 5 | I9: แก้ระดับฝ่าย | J9: {=_xlfn.IFS( I9="แก้ทั้งองค์กร", 1, I9="แก้ข้ามรอง/ผู้ช่วยขึ้นตรง", 2, I9="ต้องแต่งตั้งคณะทำงานเพื่อแก้ไข OFI", 3, I9="แก้ภายในผู้ช่วยเดียวกัน", 4, I9="แก้ระดับฝ่าย", 5, TRUE, "" )} -> 5 | L9: {=_xlfn.IFS( K9="ไม่มีผลกระทบ / ไม่เกี่ยวข้อง", 1, K9="มีผลกระทบ / เกี่ยวข้อง", 5, TRUE, "" )} | N9: {=_xlfn.IFS( M9="มีความจำเป็นต้องขออนุมัติตั้งงบประมาณเพิ่มเติม", 1, M9="สามารถตั้งงบเพียงพอ อยู่ในแผนงาน", 3, M9="ไม่ต้องใช้งบประมาณ", 5, TRUE, "" )} | P9: {=_xlfn.IFS( O9="ค่าใช้จ่ายสูงมากกว่า 500000 บาท", 1, O9="ผ่านการอนุมัติจากสายงาน", 3, O9="ไม่ต้องใช้เทคโนโลยี", 5, TRUE, "" )} | Q9: =SUM(F9*0.3,H9*0.3,J9*0.15,L9*0.15,N9*0.05,P9*0.05) -> #VALUE!
E11: 1. น้ำหนักคะแนนตามเกณฑ์รายข้อ | F11: คะแนน | G11: 2. ระดับ OFI ที่ได้รับ | H11: คะแนน | I11: 3. ความง่ายในการแก้ | J11: คะแนน | K11: 4. ผลกระทบต่อความสำเร็จของ Strategic Objective | L11: คะแนน | M11: 5. งบประมาณที่ใช้ | N11: คะแนน | O11: เทคโนโลยีดิจิทัล | P11: คะแนน
E12: 1-2 | F12: 1 | G12: L5 | H12: 1 | I12: ทั้งองค์กร | J12: 1 | K12: ไม่มีผลกระทบ / ไม่เกี่ยวข้อง | L12: 1 | M12: จำเป็นต้องขออนุมัติงบประมาณเพิ่มเติม | N12: 1 | O12: ค่าใช้จ่ายสูงมากกว่า 500,000 บาท | P12: 1
E13: 3-5 | F13: 2 | G13: L4 | H13: 2 | I13: ข้ามรอง / ผู้ช่วยขึ้นตรง | J13: 2 | K13: มีผลกระทบ / เกี่ยวข้อง | L13: 5 | M13: งบประมาณเพียงพอ อยู่ในแผนงาน | N13: 3 | O13: ผ่านการอนุมัติจากสายงาน | P13: 3
E14: 6-10 | F14: 3 | G14: L3 | H14: 5 | I14: ต้องแต่งตั้งคณะทำงาน(Cross Func.) เพื่อแก้ไข OFI | J14: 3 | M14: ไม่ต้องใช้งบประมาณ | N14: 5 | O14: ไม่ต้องใช้เทคโนโลยี | P14: 5
E15: 11-15 | F15: 4 | G15: L2 | H15: 5 | I15: ภายในผู้ช่วยเดียวกัน | J15: 4
E16: 15+ | F16: 5 | G16: L1 | H16: 5 | I16: ระดับฝ่าย | J16: 5
E17: Note: สามารถ Adjust ใหม่ให้เหมาะสมตาม Range น้ำหนักของเกณฑ์แต่ละ Enabler | G17: Note: a) HCM & KM ต้องทำครบทุก Level b) Enablers อื่นๆ จำเป็นต้องแก้ OFI Level ต่ำสุด เป็น 1st Priority เพื่อข้าม Band ไปเก็บคะแนนใน Level ที่สูงขึ้นต่อไป

Sheet รวม OFI  Health Check2564
A1: สรุป OFI Health Check 2564 : HCM และแผนการปรับปรุง
A2: Code Plan | B2: หัวข้อ : HCM | C2: Score​ | D2: Wt.​ | E2: หัวข้อย่อย | F2: OFI Code | G2: Level | H2: OFI​ | I2: Key Process Owner​ | J2: สรุปแนวทางการแก้ไข | K2: มีแผน 2564​ (พ.ย.64-ก.พ. 65)​ | L2: มีแผน 2565​ | M2: มีแผน 2566​ | N2: Remark
A3: HCM_01 | B3: 2.​การบริหารทุนมนุษย์ | C3: 4.4 | D3: 25 | E3: 2.1อัตรากำลัง [3.0000] | F3: HCM_2.1-1 | G3: L4 | H3: ​ ไม่พบหลักฐานการวิเคราะห์ความเพียงพอเชิงปริมาณของอัตรากำลังทั้งระยะสั้นและระยะยาว ที่จะสนับสนุนการดำเนินงานให้บรรลุผลสำเร็จ (L4) | I3: พอญ. ทีม workforce | N3: ทำแผนแล้วเสร็จ
A4: HCM_02 | B4: 2.​การบริหารทุนมนุษย์ | C4: 4.4 | D4: 25 | E4: 2.1อัตรากำลัง [3.0000] | F4: HCM_2.1-2 | G4: L5 | H4: ไม่พบหลักฐานแสดงผลลัพธ์การปรับปรุงกระบวนการโดยการใช้ข้อมูลป้อนกลับตามแผนอัตรากำลังประจำปี ในภาพรวมของ ปตท. เพื่อให้สอดคล้องกับการเปลี่ยนแปลงเพื่อการปรับปรุงอย่างครบถ้วน (L5) | I4: พอญ. ทีม workforce | N4: ทำแผนแล้วเสร็จ
A5: HCM_03 | B5: 3.การพัฒนาทุนมนุษย์ | C5: 4.0667 | D5: 25 | E5: 3.1 การเรียนรู้และการพัฒนา [4.0000] | F5: HCM_3.1-1 | G5: L4 | H5: ไม่พบหลักฐานแสดงกระบวนการและการวิเคราะห์ความเชื่อมโยงของระบบการเรียนรู้และการพัฒนากับแผนยุทธศาสตร์องค์กร และแผนงาน/ระบบงานที่สำคัญ เพื่อให้มั่นใจว่ามีประสิทธิภาพในการดำเนินการได้ครอบคลุม ครบถ้วน และเป็นไปในทิศทางเดียวกัน (พบเพียงตัวอย่างที่แสดงการเชื่อมโยง) (L4) | I5: พนญ. (LO Team : พอญ./ศบญ./บคญ./บทญ.) | K5: Yes | L5: Yes | M5: Yes | N5: ทำแผนแล้วเสร็จ
A6: HCM_04 | B6: 3.การพัฒนาทุนมนุษย์ | C6: 4.0667 | D6: 25 | E6: 3.1 การเรียนรู้และการพัฒนา [4.0000] | F6: HCM_3.1-2 | G6: L5 | H6: ไม่พบหลักฐานแสดงการทบทวนกระบวนการและที่มาในการนำข้อมูลป้อนเข้าตามแผนงานประจำปี มาใช้ในการปรับปรุง เพื่อให้มั่นใจว่ามีการดำเนินการอย่างมีประสิทธิภาพครบถ้วนและครอบคลุมการเปลี่ยนแปลงทั้งหมด รวมถึงการระบุแนวทางผลการปรับปรุง และผลลัพธ์ร้อยละการดำเนินงานเทียบกับแผนงานประจำปีตามที่เป้าหมายกำหนด (L5) | I6: พนญ. (LO Team : พอญ./ศบญ./บคญ./บทญ.) | K6: Yes | L6: Yes | M6: Yes | N6: ทำแผนแล้วเสร็จ
A7: HCM_05 | B7: 3.การพัฒนาทุนมนุษย์ | C7: 4.0667 | D7: 25 | E7: 3.2 การสืบทอดตำแหน่ง/การบริหารจัดการคนเก่ง/การจัดการสายอาชีพ [4.1667] | F7: HCM_3.2-1 | G7: L4 | H7: ไม่พบหลักฐานกระบวนการวิเคราะห์และบูรณาการเชื่อมโยงของแผนงานที่สำคัญ (1.การสืบทอดตำแหน่ง, 2.การบริหารจัดการคนเก่ง และ 3.การจัดการความก้าวหน้าในสายอาชีพ) กับแผนงาน/ระบบงานที่สำคัญอย่างครบถ้วน (L4) 1.การสืบทอดตำแหน่ง | I7: ศบญ. | J7: 1.การสืบทอดตำแหน่ง เลือกประเด็นปรับปรุง : กำหนด successor ของตำแหน่งเป้าหมายในปี 2566 – 2568 สำหรับระดับ VP ขึ้นไป (เชื่อมโยงกับ SP/ RM&IC แรงจูงใจ การพัฒนาและการรักษาบุคลากร /HCM ยุทธศาสตร์,กลยุทธ์, การเรียนรู้และการพัฒนา/ DT การนำระบบ Digital มาสนับสนุนงานด้านการบริหารจัดการ) | L7: Yes | N7: ทำแผนแล้วเสร็จ
A8: HCM_06 | B8: 3.การพัฒนาทุนมนุษย์ | C8: 4.0667 | D8: 25 | E8: 3.2 การสืบทอดตำแหน่ง/การบริหารจัดการคนเก่ง/การจัดการสายอาชีพ [4.1667] | F8: HCM_3.2-2 | G8: L4 | H8: ไม่พบหลักฐานกระบวนการวิเคราะห์และบูรณาการเชื่อมโยงของแผนงานที่สำคัญ (1.การสืบทอดตำแหน่ง, 2.การบริหารจัดการคนเก่ง และ 3.การจัดการความก้าวหน้าในสายอาชีพ) กับแผนงาน/ระบบงานที่สำคัญอย่างครบถ้วน (L4) 2.การบริหารจัดการคนเก่ง | I8: ศบญ. | J8: พัฒนาและปิด gap พนักงานกลุ่ม VP Pool ขึ้นไป ให้มีความพร้อมตาม New Core Competencies ที่มีความสอดคล้องกับแผนสืบทอดตำแหน่ง (เชื่อมโยงกับ SP/ HCM ยุทธศาสตร์/กลยุทธ์/ การเรียนรู้และการพัฒนา/DT / KM&IM) | L8: Yes | N8: ทำแผนแล้วเสร็จ
J9: พัฒนารูปแบบใหม่ในการเตรียมพนักงาน ให้มีความพร้อมและลงลึกในธุรกิจใหม่แบบเฉพาะเจาะจง (เชื่อมโยงกับ SP/ HCM ยุทธศาสตร์/กลยุทธ์/ ระบบประเมินผลการปฏิบัติงาน /การเรียนรู้และการพัฒนา) | L9: Yes
A10: HCM_07 | B10: 3.การพัฒนาทุนมนุษย์ | C10: 4.0667 | D10: 25 | E10: 3.2 การสืบทอดตำแหน่ง/การบริหารจัดการคนเก่ง/การจัดการสายอาชีพ [4.1667] | F10: HCM_3.2-3 | G10: L4 | H10: ไม่พบหลักฐานกระบวนการวิเคราะห์และบูรณาการเชื่อมโยงของแผนงานที่สำคัญ (1.การสืบทอดตำแหน่ง, 2.การบริหารจัดการคนเก่ง และ 3.การจัดการความก้าวหน้าในสายอาชีพ) กับแผนงาน/ระบบงานที่สำคัญอย่างครบถ้วน (L4) 3.การจัดการความก้าวหน้าในสายอาชีพ | I10: ศบญ. | J10: ทีม Career : ทบทวนกระบวนการแต่งตั้งคณะกรรมการ Career Counselling Team (CCT) เพื่อให้มีความเป็นปัจจุบันและสอดคล้องเหมาะสมกับการเปลี่ยนแปลง ในกรณีมีการปรับโครงสร้าง และ/หรือ มีการแต่งตั้ง โยกย้าย ผู้บริหารดำรงตำแหน่งตามโครงสร้างใหม่ในแต่ละสายอาชีพ และเพื่อให้ได้ผู้แทนจากสายอาชีพที่เหมาะสม เป็นผู้พิจารณาแนวทางการพัฒนาพนักงานให้มีความเชี่ยวชาญและก้าวหน้าในสายอาชีพ สอดคล้องกับทิศทางการดำเนินธุรกิจขององค์กร​ (เชื่อมโยงกับ SP การเชื่อมโยงกับแผนยุทธศาสตร์ ตามทิศทางและเป้าหมายองค์กรขององค์กร/ HCM การเรียนรู้และการพัฒนา) | L10: Yes | N10: ทำแผนแล้วเสร็จ
A11: HCM_08 | B11: 4. สภาพแวดล้อมที่สนับสนุนการบริหารและพัฒนาทุนมนุษย์ | C11: 3.8565 | D11: 20 | E11: 4.1 ความผูกพันองค์กร/ค่านิยมและวัฒนธรรมองค์กร/การจัดการการเปลี่ยนแปลง/จรรยาบรรณและจริยธรรม [3.6071] | F11: HCM_4.1-1 | G11: L3 | H11: ไม่พบหลักฐานแสดงกระบวนการติดตามและประเมินผลด้านการจัดการการเปลี่ยนแปลง (Change Management) ในช่วงต่างๆ : Pre Change / Change / Post Change(L3) | I11: พอญ. ทีมโครงสร้าง | N11: บอญ. ช่วยจัดทำแผน สรุปผลนำเสนอ ผกญ. และรอนัดประชุม สผญ.
A12: HCM_09 | B12: 4. สภาพแวดล้อมที่สนับสนุนการบริหารและพัฒนาทุนมนุษย์ | C12: 3.8565 | D12: 20 | E12: 4.1 ความผูกพันองค์กร/ค่านิยมและวัฒนธรรมองค์กร/การจัดการการเปลี่ยนแปลง/จรรยาบรรณและจริยธรรม [3.6071] | F12: HCM_4.1-2 | G12: L3 | H12: ไม่พบหลักฐานแสดงกระบวนการประเมินผลการดำเนินงานที่มีประสิทธิภาพ และร้อยละของผลลัพธ์การดำเนินงานเทียบกับแผนงานประจำปีของการมีคณะกรรมการด้านบุคคลที่สอดคล้องตามเป้าหมายที่กำหนด (L3) - HRAC, HRMC, HRC - คณะกรรมการทุน - CCT/Sub-CCT | I12: นทญ./ศบญ./ บคญ./ บทญ. | L12: Yes | N12: รอดำเนินการ
A13: HCM_10 | B13: 4. สภาพแวดล้อมที่สนับสนุนการบริหารและพัฒนาทุนมนุษย์ | C13: 3.8565 | D13: 20 | E13: 4.1 ความผูกพันองค์กร/ค่านิยมและวัฒนธรรมองค์กร/การจัดการการเปลี่ยนแปลง/จรรยาบรรณและจริยธรรม [3.6071] | F13: HCM_4.1-3 | G13: L4 | H13: ไม่พบหลักฐานที่แสดงกระบวนการวิเคราะห์ความเชื่อมโยงระหว่างแผนยุทธศาสตร์องค์กร กับแผนการสร้างสภาพแวดล้อมที่สนับสนุนการบริหารและพัฒนาทุนมนุษย์ ดังต่อไปนี้ 1) การสร้างความผูกพันองค์กร | I13: นทญ. ทีม Strategy | L13: Yes | N13: ทำแผนแล้วเสร็จ รอหารือเพิ่มเติม
H14: 2) การเสริมสร้างค่านิยมและวัฒนธรรมองค์กร | I14: พอญ. ทีม SPIRIT | L14: Yes | N14: รอ นทญ. รวมภาพแผนกลยุทธ์ใหญ่ และแผนงานที่สำคัญ
H15: 3) การจัดการการเปลี่ยนแปลง | I15: พอญ. ทีม โครงสร้าง | L15: Yes | N15: รอ นทญ. รวมภาพแผนกลยุทธ์ใหญ่ และแผนงานที่สำคัญ
H16: 4) การจัดทำและสื่อสารคู่มือจรรยาบรรณและจริยธรรม | I16: กธญ. | L16: Yes
H17: 5) การสื่อสารและเปิดเผยข้อมูลความขัดแย้งทางผลประโยชน์ | I17: กธญ. | L17: Yes
H18: 6) การรับฟังและบริหารข้อร้องเรียน | I18: กธญ. | L18: Yes
H19: 7) คณะกรรมการด้านบุคคล | I19: นทญ./ศบญ./ บคญ./ บทญ. | L19: Yes
H20: รวมถึงความเชื่อมโยงกับแผนงาน/ระบบงานที่สำคัญอื่นๆ ที่เกี่ยวข้อง (ปัจจุบันมีการแสดงตัวอย่างความเชื่อมโยง แต่กระบวนการในการวิเคราะห์ความเชื่อมโยงยังไม่ชัดเจนว่าเมื่อไรจะเชื่อมโยงกับยุทธศาตร์หรือเป็นความเชื่อมโยงในลักษณะ BAU)(L4)
A21: HCM_11 | B21: 4. สภาพแวดล้อมที่สนับสนุนการบริหารและพัฒนาทุนมนุษย์ | C21: 3.8565 | D21: 20 | E21: 4.1 ความผูกพันองค์กร/ค่านิยมและวัฒนธรรมองค์กร/การจัดการการเปลี่ยนแปลง/จรรยาบรรณและจริยธรรม [3.6071] | F21: HCM_4.1-4 | G21: L5 | H21: ไม่พบหลักฐานแสดงการใช้ข้อมูลป้อนกลับจากการดำเนินงานตามแผนงานประจำปี มาปรับปรุงพัฒนาการดำเนินงานด้าน คณะกรรมการด้านบุคคล (L5) - HRAC, HRMC, HRC - คณะกรรมการทุน - CCT/Sub-CCT | I21: นทญ./ศบญ./ บคญ./ บทญ. | L21: Yes | N21: รอดำเนินการ
A22: HCM_12 | B22: 4. สภาพแวดล้อมที่สนับสนุนการบริหารและพัฒนาทุนมนุษย์ | C22: 3.8565 | D22: 20 | E22: 4.4 บทบาทของสายงาน HR และการสนับสนุนจากผู้บริหาร [3.4095] | F22: HCM_4.4-1 | G22: L1 | H22: ไม่พบหลักฐานการกำหนดกระบวนการส่งเสริมพัฒนาผู้แทนของสายงาน (HR Coordinator) (L1) | I22: บคญ., บทญ. | L22: Yes | N22: ทำแผนแล้วเสร็จ
A23: HCM_13 | B23: 4. สภาพแวดล้อมที่สนับสนุนการบริหารและพัฒนาทุนมนุษย์ | C23: 3.8565 | D23: 20 | E23: 4.4 บทบาทของสายงาน HR และการสนับสนุนจากผู้บริหาร [3.4095] | F23: HCM_4.4-2 | G23: L2 | H23: ไม่พบหลักฐานการกำหนดกระบวนการ/แนวทาง/วิธีการในการสอบทานการดำเนินงานของกระบวนการที่สำคัญด้าน HR (HR audit) (L2) | I23: นทญ. | L23: Yes | N23: ทำแผนแล้วเสร็จ
A24: HCM_14 | B24: 4. สภาพแวดล้อมที่สนับสนุนการบริหารและพัฒนาทุนมนุษย์ | C24: 3.8565 | D24: 20 | E24: 4.4 บทบาทของสายงาน HR และการสนับสนุนจากผู้บริหาร [3.4095] | F24: HCM_4.4-3 | G24: L2 | H24: ไม่พบหลักฐานกระบวนการส่งเสริม/พัฒนาระบบ/ทีมงานของบุคลากรที่รับผิดชอบด้าน HR ในการดำเนินงานเพื่อให้ได้การรับคุณวุฒิวิชาชีพ (พบเพียงการทบทวน Development Framework ของ HR Academy และการทำ HR on Shelf) (L2) | I24: บคญ., บทญ. | L24: Yes | M24: Yes | N24: ทำแผนแล้วเสร็จ
A25: HCM_15 | B25: 4. สภาพแวดล้อมที่สนับสนุนการบริหารและพัฒนาทุนมนุษย์ | C25: 3.8565 | D25: 20 | E25: 4.4 บทบาทของสายงาน HR และการสนับสนุนจากผู้บริหาร [3.4095] | F25: HCM_4.4-4 | G25: L5 | H25: ไม่พบหลักฐานกลไกหรือกระบวนการติดตามและประเมินผลการดำเนินงาน และร้อยละของผลลัพธ์การดำเนินงานเทียบกับแผนงานประจำปี ด้านการพัฒนาผู้แทนของสายงาน (HR Coordinator) (L5) | I25: บคญ., บทญ. | L25: Yes | N25: รอดำเนินการ
A26: HCM_16 | B26: 4. สภาพแวดล้อมที่สนับสนุนการบริหารและพัฒนาทุนมนุษย์ | C26: 3.8565 | D26: 20 | E26: 4.4 บทบาทของสายงาน HR และการสนับสนุนจากผู้บริหาร [3.4095] | F26: HCM_4.4-5 | G26: L5 | H26: ไม่พบหลักฐานกลไกหรือกระบวนการติดตามและประเมินผลการดำเนินงาน และร้อยละของผลลัพธ์การดำเนินงานเทียบกับแผนงานประจำปี ด้านการส่งเสริมให้บุคลากรของหน่วยงานที่รับผิดชอบด้าน HR ได้รับคุณวุฒิวิชาชีพ (พบเพียงแต่การนำหลักการ Kirkpatrick Model มาใช้ในการประเมิน HR Academy) (L5) | I26: บคญ., บทญ. | L26: Yes | M26: Yes | N26: รอดำเนินการ | O26: ดำเนินการเปรียบเทียบสิ่งที่ ปตท. ดำเนินการ รอเพิ่มเติมเรื่อง การImprovemenrt กระบวนการ
A27: HCM_17 | B27: 4. สภาพแวดล้อมที่สนับสนุนการบริหารและพัฒนาทุนมนุษย์ | C27: 3.8565 | D27: 20 | E27: 4.4 บทบาทของสายงาน HR และการสนับสนุนจากผู้บริหาร [3.4095] | F27: HCM_4.4-6 | G27: L5 | H27: ไม่พบหลักฐานกลไกหรือกระบวนการติดตามและประเมินผลการดำเนินงาน และร้อยละของผลลัพธ์การดำเนินงานเทียบกับแผนงานประจำปี ด้านการกำหนดแนวทาง/วิธีการในการสอบทานการดำเนินงานของกระบวนการที่สำคัญด้าน HR (HR audit) (L5) | I27: นทญ. | L27: Yes | N27: รอดำเนินการ | O27: บอญ.ช่วยเซตกระบวนการ
